Workbook

Sheet README
A1: Cement Sector - Financial Model
A2: UltraTech | Shree Cement | Ambuja | JK Cement | Dalmia Bharat
A4: Project | B4: Research & Investment Recommendation in the Cement Sector -
A5: Companies covered | B5: UltraTech (sector leader), Shree Cement (margin leader), Ambuja (Adani-group consolidator), JK Cement (grey + white cement growth), Dalmia Bharat (south/east-focused, low leverage).
A6: Base period | B6: FY26 (year ended 31-Mar-2026) for current ratios; FY24-FY26 for growth trends.
A8: Blue text | B8: Hardcoded/source input.
A10: Green text | B10: Formula linking to another worksheet.
A12: Sheet guide
A13: Company Rationale | B13: Why these five companies
A14: Master Data (FY26) | B14: Single source of truth for FY26 inputs, market data and derived items.
A15: Hist - <company> | B15: FY24-FY26 trends (FY26 links to Master Data)
A16: Ratio Analysis | B16: Growth, profitability, return, leverage and valuation ratios (all formulas)
A17: CCA Valuation | B17: Peer-median P/E and P/B implied prices
A18: Qualitative Analysis | B18: Positioning, catalysts, risks and watch triggers
A19: Investment Scorecard | B19: Weighted rank-based score
A20: Scorecard Sensitivity | B20: Score under 3 alternative weightings
A21: FY27-28E Assumptions | B21: Forward growth, margin assumptions and projected EPS
A22: Forward & Historical Valuation | B22: Historical implied P/E and bear/base/bull prices
A23: Valuation Justification | B23: Convergence test for peer-median multiples
A24: Rating Rationale | B24: Threshold reasoning, qualitative rubric, robustness
... A29: Recommendation Matrix | B29: Rule-based rating

Sheet Company Rationale
A1: Why These 5 Companies?
A3: Selection logic
A4: Three national leaders (UltraTech, Ambuja, Shree), a fast-growing mid-cap (JK Cement) and a low-leverage regional player (Dalmia) expose trade-offs in scale, margin, growth, leverage and valuation.
A6: Company | B6: Positioning and role in the comparison
A7: UltraTech | B7: Largest producer: 200.1 MTPA India capacity, about 27% of industry capacity; the benchmark for scale and pricing.
A8: Shree Cement | B8: Highest EBITDA margin in the set; 69.3 MTPA capacity growing towards 80+ MTPA; shares trade on the richest P/E.
A9: Ambuja | B9: Adani-group consolidator: 109 MTPA across Ambuja and ACC, target 119 MTPA; almost no debt but a large, low-return equity base.
A10: JK Cement | B10: Mid-size grey and white cement producer, 32.26 MTPA grey capacity with a plan for about 50 MTPA by FY30; best ROE but heaviest debt.
A11: Dalmia Bharat | B11: 54.7 MTPA after a recent acquisition, 67 MTPA targeted by FY28; south and east focus, low leverage, profit recovering from FY25.

Sheet Master Data (FY26)
A1: Master Data - FY26 (Year ended 31-Mar-2026), Rs crore
A3: Metric | B3: UltraTech | C3: Shree Cement | D3: Ambuja | E3: JK Cement | F3: Dalmia Bharat | G3: Note
A4: Revenue (Rs Cr) | B4: 88511.5 | C4: 20943.47 | D4: 40655.7 | E4: 13722.3 | F4: 14804 | G4: FY26 consolidated, company releases / S&P
A5: EBITDA (Rs Cr) | B5: 17020.2 | C5: 4638 | D5: 6374.3 | E5: 2374 | F5: 3083 | G5: Operating profit excl. other income (Ambuja: S&P EBITDA)
A6: PAT attributable (Rs Cr) | B6: 8165.64 | C6: 1748.66 | D6: 4728.2 | E6: 992.49 | F6: 1157.5 | G6: Consolidated PAT attributable where available
A7: Equity / Net Worth (Rs Cr) | B7: =2399.42*B9 -> 70614.931 | C7: =6239.23*C9 -> 22511.766 | D7: =205.9*D9 -> 52546.777 | E7: =900.85*E9 -> 6960.6878 | F7: 17979 | G7: Book value/share x shares; Dalmia = reported shareholders fund; Ambuja = BVPS 205.90 x shares (owners equity, excludes minority interest)
A8: Current Market Price (Rs) | B8: 10830.3 | C8: 21908.95 | D8: 384.05 | E8: 5030.3 | F8: 1690
A9: Shares Outstanding (Cr) | B9: 29.43 | C9: 3.6081 | D9: =107326.6/420.55 -> 255.20533 | E9: 7.7268 | F9: 18.757 | G9: Exchange data or market cap / price
A10: Market Capitalization (Rs Cr) | B10: =B8*B9 -> 318735.73 | C10: =C8*C9 -> 79049.682 | D10: =D8*D9 -> 98011.606 | E10: =E8*E9 -> 38868.122 | F10: =F8*F9 -> 31699.33 | G10: Price x shares
A11: Total Debt (Rs Cr) | B11: 23755.1 | C11: 1868 | D11: 866 | E11: =0.87*E7 -> 6055.7984 | F11: 7428 | G11: Gross borrowings; UltraTech incl. leases (S&P); Shree, Ambuja, Dalmia as reported; JK = D/E 0.87 x equity
A13: Supporting inputs / derived figures
A14: FY26 Revenue Growth | B14: =B4/'Hist - UltraTech'!C4-1 -> 0.16531345 | C14: =C4/'Hist - Shree'!C4-1 -> 0.086120139 | D14: =D4/'Hist - Ambuja'!C4-1 -> 0.15053316 | E14: =E4/'Hist - JK Cement'!C4-1 -> 0.15515841 | F14: =F4/'Hist - Dalmia'!C4-1 -> 0.058941345
A15: 2Y Revenue CAGR (FY24-FY26) | B15: =(B4/'Hist - UltraTech'!B4)^(1/2)-1 -> 0.11725402 | C15: =(C4/'Hist - Shree'!B4)^(1/2)-1 -> 0.013138433 | D15: =(D4/'Hist - Ambuja'!B4)^(1/2)-1 -> 0.10727649 | E15: =(E4/'Hist - JK Cement'!B4)^(1/2)-1 -> 0.089706868 | F15: =(F4/'Hist - Dalmia'!B4)^(1/2)-1 -> 0.0038385249
A16: Book Value per Share (Rs) | B16: =B7/B9 -> 2399.42 | C16: =C7/C9 -> 6239.23 | D16: =D7/D9 -> 205.9 | E16: =E7/E9 -> 900.85 | F16: =F7/F9 -> 958.52215
A17: Debt / Equity | B17: =B11/B7 -> 0.33640336 | C17: =C11/C7 -> 0.082978831 | D17: =D11/D7 -> 0.016480554 | E17: =E11/E7 -> 0.87 | F17: =F11/F7 -> 0.41314867

Sheet Hist - UltraTech
A1: UltraTech - Historical Financials (FY24-FY26)
A2: Consolidated, Rs crore. FY26 links to Master Data. Orange fill = derived or estimated input (see Basis column and Data Quality Log).
A3: Metric | B3: FY24 | C3: FY25 | D3: FY26
A4: Revenue (Rs Cr) | B4: 70908.1 | C4: 75955.1 | D4: ='Master Data (FY26)'!B4 -> 88511.5
A5: Revenue YoY Growth % | B5: N/A | C5: =IFERROR(C4/B4-1,"N/A") -> 0.071176636 | D5: =IFERROR(D4/C4-1,"N/A") -> 0.16531345
A6: EBITDA (Rs Cr) | B6: 12968.6 | C6: 12558 | D6: ='Master Data (FY26)'!B5 -> 17020.2
A7: EBITDA Margin % | B7: =IFERROR(B6/B4,"N/A") -> 0.18289307 | C7: =IFERROR(C6/C4,"N/A") -> 0.16533452 | D7: =IFERROR(D6/D4,"N/A") -> 0.19229366
A8: PAT (Rs Cr) | B8: 7005 | C8: 6039.1 | D8: ='Master Data (FY26)'!B6 -> 8165.64
A9: PAT YoY Growth % | B9: N/A | C9: =IFERROR(C8/B8-1,"N/A") -> -0.13788722 | D9: =IFERROR(D8/C8-1,"N/A") -> 0.35212863
A10: Net Margin % | B10: =IFERROR(B8/B4,"N/A") -> 0.098789842 | C10: =IFERROR(C8/C4,"N/A") -> 0.079508815 | D10: =IFERROR(D8/D4,"N/A") -> 0.092255131
A12: 2Y Revenue CAGR (FY24-FY26) | D12: =IFERROR((D4/B4)^(1/2)-1,"N/A") -> 0.11725402

Sheet Hist - Shree
A1: Shree Cement - Historical Financials (FY24-FY26)
A2: Consolidated, Rs crore. FY26 links to Master Data. Orange fill = derived or estimated input (see Basis column and Data Quality Log).
A3: Metric | B3: FY24 | C3: FY25 | D3: FY26
A4: Revenue (Rs Cr) | B4: 20403.8 | C4: 19282.83 | D4: ='Master Data (FY26)'!C4 -> 20943.47
A5: Revenue YoY Growth % | B5: N/A | C5: =IFERROR(C4/B4-1,"N/A") -> -0.054939276 | D5: =IFERROR(D4/C4-1,"N/A") -> 0.086120139
A6: EBITDA (Rs Cr) | B6: 4517 | C6: 3934 | D6: ='Master Data (FY26)'!C5 -> 4638
A7: EBITDA Margin % | B7: =IFERROR(B6/B4,"N/A") -> 0.22138033 | C7: =IFERROR(C6/C4,"N/A") -> 0.2040157 | D7: =IFERROR(D6/D4,"N/A") -> 0.22145327
A8: PAT (Rs Cr) | B8: 2396.16 | C8: 1123.8 | D8: ='Master Data (FY26)'!C6 -> 1748.66
A9: PAT YoY Growth % | B9: N/A | C9: =IFERROR(C8/B8-1,"N/A") -> -0.5309996 | D9: =IFERROR(D8/C8-1,"N/A") -> 0.5560242
A10: Net Margin % | B10: =IFERROR(B8/B4,"N/A") -> 0.11743695 | C10: =IFERROR(C8/C4,"N/A") -> 0.058279827 | D10: =IFERROR(D8/D4,"N/A") -> 0.083494282
A12: 2Y Revenue CAGR (FY24-FY26) | D12: =IFERROR((D4/B4)^(1/2)-1,"N/A") -> 0.013138433

Sheet Hist - Ambuja
A1: Ambuja - Historical Financials (FY24-FY26)
A2: Consolidated, Rs crore. FY26 links to Master Data. Orange fill = derived or estimated input (see Basis column and Data Quality Log).
A3: Metric | B3: FY24 | C3: FY25 | D3: FY26 | E3: Basis / note
A4: Revenue (Rs Cr) | B4: 33159.6 | C4: 35336.4 | D4: ='Master Data (FY26)'!D4 -> 40655.7
A5: Revenue YoY Growth % | B5: N/A | C5: =IFERROR(C4/B4-1,"N/A") -> 0.065646148 | D5: =IFERROR(D4/C4-1,"N/A") -> 0.15053316
A6: EBITDA (Rs Cr) | B6: 6251.9 | C6: 5744.4 | D6: ='Master Data (FY26)'!D5 -> 6374.3
A7: EBITDA Margin % | B7: =IFERROR(B6/B4,"N/A") -> 0.18853967 | C7: =IFERROR(C6/C4,"N/A") -> 0.16256325 | D7: =IFERROR(D6/D4,"N/A") -> 0.15678736
A8: PAT (Rs Cr) | B8: 3573.4 | C8: 4303.1 | D8: ='Master Data (FY26)'!D6 -> 4728.2
A9: PAT YoY Growth % | B9: N/A | C9: =IFERROR(C8/B8-1,"N/A") -> 0.20420328 | D9: =IFERROR(D8/C8-1,"N/A") -> 0.098789245
A10: Net Margin % | B10: =IFERROR(B8/B4,"N/A") -> 0.10776366 | C10: =IFERROR(C8/C4,"N/A") -> 0.12177528 | D10: =IFERROR(D8/D4,"N/A") -> 0.11629858
A12: 2Y Revenue CAGR (FY24-FY26) | D12: =IFERROR((D4/B4)^(1/2)-1,"N/A") -> 0.10727649

Sheet Hist - JK Cement
A1: JK Cement - Historical Financials (FY24-FY26)
A2: Consolidated, Rs crore. FY26 links to Master Data. Orange fill = derived or estimated input (see Basis column and Data Quality Log).
A3: Metric | B3: FY24 | C3: FY25 | D3: FY26 | E3: Basis / note
A4: Revenue (Rs Cr) | B4: 11556 | C4: 11879.15 | D4: ='Master Data (FY26)'!E4 -> 13722.3
A5: Revenue YoY Growth % | B5: N/A | C5: =IFERROR(C4/B4-1,"N/A") -> 0.027963828 | D5: =IFERROR(D4/C4-1,"N/A") -> 0.15515841
A6: EBITDA (Rs Cr) | B6: 2006 | C6: =D6/1.17 -> 2029.0598 | D6: ='Master Data (FY26)'!E5 -> 2374
A7: EBITDA Margin % | B7: =IFERROR(B6/B4,"N/A") -> 0.17358948 | C7: =IFERROR(C6/C4,"N/A") -> 0.1708085 | D7: =IFERROR(D6/D4,"N/A") -> 0.17300307
A8: PAT (Rs Cr) | B8: 790.83 | C8: 861.12 | D8: ='Master Data (FY26)'!E6 -> 992.49
A9: PAT YoY Growth % | B9: N/A | C9: =IFERROR(C8/B8-1,"N/A") -> 0.088881302 | D9: =IFERROR(D8/C8-1,"N/A") -> 0.15255713
A10: Net Margin % | B10: =IFERROR(B8/B4,"N/A") -> 0.068434579 | C10: =IFERROR(C8/C4,"N/A") -> 0.072490035 | D10: =IFERROR(D8/D4,"N/A") -> 0.072326797
A12: 2Y Revenue CAGR (FY24-FY26) | D12: =IFERROR((D4/B4)^(1/2)-1,"N/A") -> 0.089706868

Sheet Hist - Dalmia
A1: Dalmia Bharat - Historical Financials (FY24-FY26)
A2: Consolidated, Rs crore. FY26 links to Master Data.
A3: Metric | B3: FY24 | C3: FY25 | D3: FY26 | E3: Basis / note
A4: Revenue (Rs Cr) | B4: 14691 | C4: 13980 | D4: ='Master Data (FY26)'!F4 -> 14804
A5: Revenue YoY Growth % | B5: N/A | C5: =IFERROR(C4/B4-1,"N/A") -> -0.048396978 | D5: =IFERROR(D4/C4-1,"N/A") -> 0.058941345
A6: EBITDA (Rs Cr) | B6: 2639 | C6: 2407 | D6: ='Master Data (FY26)'!F5 -> 3083
A7: EBITDA Margin % | B7: =IFERROR(B6/B4,"N/A") -> 0.17963379 | C7: =IFERROR(C6/C4,"N/A") -> 0.17217454 | D7: =IFERROR(D6/D4,"N/A") -> 0.20825453
A8: PAT (Rs Cr) | B8: 853 | C8: 699 | D8: ='Master Data (FY26)'!F6 -> 1157.5
A9: PAT YoY Growth % | B9: N/A | C9: =IFERROR(C8/B8-1,"N/A") -> -0.18053927 | D9: =IFERROR(D8/C8-1,"N/A") -> 0.65593705
A10: Net Margin % | B10: =IFERROR(B8/B4,"N/A") -> 0.05806276 | C10: =IFERROR(C8/C4,"N/A") -> 0.05 | D10: =IFERROR(D8/D4,"N/A") -> 0.078188327
A12: 2Y Revenue CAGR (FY24-FY26) | D12: =IFERROR((D4/B4)^(1/2)-1,"N/A") -> 0.0038385249

Sheet Macro & Sector Data
A1: Macro & Sector Data (sourced inputs and derived indicators)
A2: Blue = sourced input; mid-point = average of low and high. Sources are listed on the Sources & References sheet.
A3: Indicator | B3: Low | C3: High | D3: Mid-point | E3: Unit | F3: Source
A4: Real GDP growth FY26 (first advance estimate) | B4: 0.074 | C4: 0.074 | D4: =AVERAGE(B4:C4) -> 0.074 | E4: % | F4: Economic Survey 2025-26 / PIB
A5: Real GDP growth FY27 (Survey range) | B5: 0.068 | C5: 0.072 | D5: =AVERAGE(B5:C5) -> 0.07 | E5: % | F5: Economic Survey 2025-26
A6: RBI projection, real GDP growth FY27 | B6: 0.066 | C6: 0.066 | D6: =AVERAGE(B6:C6) -> 0.066 | E6: % | F6: RBI via EY / PGurus coverage
A7: Union capital expenditure FY27 (BE) | B7: 12.22 | C7: 12.22 | D7: =AVERAGE(B7:C7) -> 12.22 | E7: Rs lakh Cr | F7: Union Budget 2026-27 (PIB)
A8: Effective capital expenditure FY27 (BE) | B8: 17.15 | C8: 17.15 | D8: =AVERAGE(B8:C8) -> 17.15 | E8: Rs lakh Cr | F8: Union Budget 2026-27 (PIB)
A9: Union capex as % of GDP FY27 | B9: 0.031 | C9: 0.031 | D9: =AVERAGE(B9:C9) -> 0.031 | E9: % GDP | F9: Union Budget 2026-27
A10: Effective capex as % of GDP FY27 | B10: 0.044 | C10: 0.044 | D10: =AVERAGE(B10:C10) -> 0.044 | E10: % GDP | F10: Union Budget 2026-27 (PIB)
A11: Cement volume growth FY26 (estimate) | B11: 0.065 | C11: 0.075 | D11: =AVERAGE(B11:C11) -> 0.07 | E11: % | F11: ICRA / Crisil
A12: Cement volume growth FY27E | B12: 0.06 | C12: 0.07 | D12: =AVERAGE(B12:C12) -> 0.065 | E12: % | F12: ICRA (Dec-2025, Jul-2026)
A13: Industry installed capacity FY25 | B13: 654 | C13: 654 | D13: =AVERAGE(B13:C13) -> 654 | E13: MTPA | F13: constrofacilitator.com
A14: Industry installed capacity FY26 | B14: 702 | C14: 702 | D14: =AVERAGE(B14:C14) -> 702 | E14: MTPA | F14: constrofacilitator.com
A15: Industry installed capacity FY29E | B15: 867 | C15: 867 | D15: =AVERAGE(B15:C15) -> 867 | E15: MTPA | F15: constrofacilitator.com
... A28: Infrastructure share of cement demand (about one third) | B28: 0.33 | C28: 0.33 | D28: =AVERAGE(B28:C28) -> 0.33 | E28: % of demand | F28: Crisil

Sheet Capacity & Efficiency
A1: Capacity, market position and efficiency (indicative)
A2: Capacity is the latest reported figure (some include recent acquisitions), so per-MTPA ratios are indicative rather than precise.
A4: Company | B4: Installed capacity (MTPA) | C4: Share of industry capacity | D4: Revenue per MTPA (Rs Cr) | E4: EBITDA per MTPA (Rs Cr) | F4: PAT per MTPA (Rs Cr) | G4: Market cap per MTPA (Rs Cr) | H4: Target capacity (MTPA) | I4: Target year | J4: Planned capacity growth | K4: EBITDA/MTPA rank | L4: Capacity source / note
A5: UltraTech | B5: 200.1 | C5: =B5/'Macro & Sector Data'!$D$14 -> 0.28504274 | D5: ='Master Data (FY26)'!B4/B5 -> 442.33633 | E5: ='Master Data (FY26)'!B5/B5 -> 85.058471 | F5: ='Master Data (FY26)'!B6/B5 -> 40.807796 | G5: ='Master Data (FY26)'!B10/B5 -> 1592.8822 | H5: 240 | I5: FY28 | J5: =H5/B5-1 -> 0.1994003 | K5: =RANK(E5,$E$5:$E$9,0) -> 1 | L5: India capacity 200.1 MTPA (tradologie); domestic capacity to exceed 240 MTPA by FY28 (constrofacilitator)
A6: Shree Cement | B6: 69.3 | C6: =B6/'Macro & Sector Data'!$D$14 -> 0.098717949 | D6: ='Master Data (FY26)'!C4/B6 -> 302.21457 | E6: ='Master Data (FY26)'!C5/B6 -> 66.926407 | F6: ='Master Data (FY26)'!C6/B6 -> 25.233189 | G6: ='Master Data (FY26)'!C10/B6 -> 1140.6881 | H6: 80 | I6: Medium term | J6: =H6/B6-1 -> 0.15440115 | K6: =RANK(E6,$E$5:$E$9,0) -> 3 | L6: 69.3 MTPA as of Jun-2026; target 80+ MTPA
A7: Ambuja | B7: 109 | C7: =B7/'Macro & Sector Data'!$D$14 -> 0.15527066 | D7: ='Master Data (FY26)'!D4/B7 -> 372.98807 | E7: ='Master Data (FY26)'!D5/B7 -> 58.479817 | F7: ='Master Data (FY26)'!D6/B7 -> 43.377982 | G7: ='Master Data (FY26)'!D10/B7 -> 899.18904 | H7: 119 | I7: FY27 | J7: =H7/B7-1 -> 0.091743119 | K7: =RANK(E7,$E$5:$E$9,0) -> 4 | L7: Consolidated 109 MTPA (Ambuja and ACC), 119 MTPA by end FY27
A8: JK Cement | B8: 32.26 | C8: =B8/'Macro & Sector Data'!$D$14 -> 0.045954416 | D8: ='Master Data (FY26)'!E4/B8 -> 425.36578 | E8: ='Master Data (FY26)'!E5/B8 -> 73.589585 | F8: ='Master Data (FY26)'!E6/B8 -> 30.765344 | G8: ='Master Data (FY26)'!E10/B8 -> 1204.8395 | H8: 50 | I8: FY30 | J8: =H8/B8-1 -> 0.54990701 | K8: =RANK(E8,$E$5:$E$9,0) -> 2 | L8: Grey cement capacity; about 50 MTPA planned by FY30
A9: Dalmia Bharat | B9: 54.7 | C9: =B9/'Macro & Sector Data'!$D$14 -> 0.077920228 | D9: ='Master Data (FY26)'!F4/B9 -> 270.63985 | E9: ='Master Data (FY26)'!F5/B9 -> 56.361974 | F9: ='Master Data (FY26)'!F6/B9 -> 21.160878 | G9: ='Master Data (FY26)'!F10/B9 -> 579.51243 | H9: 67 | I9: FY28 | J9: =H9/B9-1 -> 0.22486289 | K9: =RANK(E9,$E$5:$E$9,0) -> 5 | L9: 54.7 MTPA after acquisition (Q1 FY27); about 67 MTPA by FY28
A11: Total of five companies | B11: =SUM(B5:B9) -> 465.36 | C11: =SUM(C5:C9) -> 0.66290598

Sheet Ratio Analysis
A1: Investment Valuation & Financial Metrics - FY26
A2: All formula-driven from Master Data (FY26)
A3: Metric | B3: Formula / interpretation | C3: UltraTech | D3: Shree Cement | E3: Ambuja | F3: JK Cement | G3: Dalmia Bharat
A4: Revenue (Rs Cr) | B4: Direct link | C4: ='Master Data (FY26)'!B4 -> 88511.5 | D4: ='Master Data (FY26)'!C4 -> 20943.47 | E4: ='Master Data (FY26)'!D4 -> 40655.7 | F4: ='Master Data (FY26)'!E4 -> 13722.3 | G4: ='Master Data (FY26)'!F4 -> 14804
A5: FY26 Revenue Growth | B5: FY26 / FY25 - 1 | C5: ='Master Data (FY26)'!B14 -> 0.16531345 | D5: ='Master Data (FY26)'!C14 -> 0.086120139 | E5: ='Master Data (FY26)'!D14 -> 0.15053316 | F5: ='Master Data (FY26)'!E14 -> 0.15515841 | G5: ='Master Data (FY26)'!F14 -> 0.058941345
A6: 2Y Revenue CAGR | B6: (FY26/FY24)^(1/2)-1 | C6: ='Master Data (FY26)'!B15 -> 0.11725402 | D6: ='Master Data (FY26)'!C15 -> 0.013138433 | E6: ='Master Data (FY26)'!D15 -> 0.10727649 | F6: ='Master Data (FY26)'!E15 -> 0.089706868 | G6: ='Master Data (FY26)'!F15 -> 0.0038385249
A7: EBITDA (Rs Cr) | B7: Direct link | C7: ='Master Data (FY26)'!B5 -> 17020.2 | D7: ='Master Data (FY26)'!C5 -> 4638 | E7: ='Master Data (FY26)'!D5 -> 6374.3 | F7: ='Master Data (FY26)'!E5 -> 2374 | G7: ='Master Data (FY26)'!F5 -> 3083
A8: EBITDA Margin | B8: EBITDA / Revenue | C8: =C7/C4 -> 0.19229366 | D8: =D7/D4 -> 0.22145327 | E8: =E7/E4 -> 0.15678736 | F8: =F7/F4 -> 0.17300307 | G8: =G7/G4 -> 0.20825453
A9: PAT (Rs Cr) | B9: Direct link | C9: ='Master Data (FY26)'!B6 -> 8165.64 | D9: ='Master Data (FY26)'!C6 -> 1748.66 | E9: ='Master Data (FY26)'!D6 -> 4728.2 | F9: ='Master Data (FY26)'!E6 -> 992.49 | G9: ='Master Data (FY26)'!F6 -> 1157.5
A10: Net Margin | B10: PAT / Revenue | C10: =C9/C4 -> 0.092255131 | D10: =D9/D4 -> 0.083494282 | E10: =E9/E4 -> 0.11629858 | F10: =F9/F4 -> 0.072326797 | G10: =G9/G4 -> 0.078188327
A11: P/E Ratio | B11: Market cap / PAT | C11: ='Master Data (FY26)'!B10/C9 -> 39.033772 | D11: ='Master Data (FY26)'!C10/D9 -> 45.205862 | E11: ='Master Data (FY26)'!D10/E9 -> 20.729158 | F11: ='Master Data (FY26)'!E10/F9 -> 39.16223 | G11: ='Master Data (FY26)'!F10/G9 -> 27.38603
A12: P/B Ratio | B12: Market cap / equity | C12: ='Master Data (FY26)'!B10/'Master Data (FY26)'!B7 -> 4.5137158 | D12: ='Master Data (FY26)'!C10/'Master Data (FY26)'!C7 -> 3.511483 | E12: ='Master Data (FY26)'!D10/'Master Data (FY26)'!D7 -> 1.8652258 | F12: ='Master Data (FY26)'!E10/'Master Data (FY26)'!E7 -> 5.5839485 | G12: ='Master Data (FY26)'!F10/'Master Data (FY26)'!F7 -> 1.7631309
A13: ROE | B13: PAT / FY26 equity | C13: =C9/'Master Data (FY26)'!B7 -> 0.11563617 | D13: =D9/'Master Data (FY26)'!C7 -> 0.077677603 | E13: =E9/'Master Data (FY26)'!D7 -> 0.089980781 | F13: =F9/'Master Data (FY26)'!E7 -> 0.14258505 | G13: =G9/'Master Data (FY26)'!F7 -> 0.064380666
A14: Debt / Equity | B14: Total debt / equity | C14: ='Master Data (FY26)'!B17 -> 0.33640336 | D14: ='Master Data (FY26)'!C17 -> 0.082978831 | E14: ='Master Data (FY26)'!D17 -> 0.016480554 | F14: ='Master Data (FY26)'!E17 -> 0.87 | G14: ='Master Data (FY26)'!F17 -> 0.41314867
A15: P/S Ratio | B15: Market cap / revenue | C15: ='Master Data (FY26)'!B10/C4 -> 3.6010657 | D15: ='Master Data (FY26)'!C10/D4 -> 3.774431 | E15: ='Master Data (FY26)'!D10/E4 -> 2.4107716 | F15: ='Master Data (FY26)'!E10/F4 -> 2.8324787 | G15: ='Master Data (FY26)'!F10/G4 -> 2.1412679

Sheet CCA Valuation
A1: Comparable Company Analysis - Peer-median P/E and P/B
A2: Each company is valued at the median multiple of the other four
A4: Company | B4: Price (Rs) | C4: Shares (Cr) | D4: Peer Median P/E (x) | E4: P/E Implied Price (Rs) | F4: Peer Median P/B (x) | G4: P/B Implied Price (Rs) | H4: Blended upside at full peer-median convergence | I4: Adjusted P/E implied price (Rs) | J4: Adjusted P/B implied price (Rs) | K4: Adjusted blended upside
A5: UltraTech | B5: ='Master Data (FY26)'!B8 -> 10830.3 | C5: ='Master Data (FY26)'!B9 -> 29.43 | D5: =MEDIAN('Ratio Analysis'!D11,'Ratio Analysis'!E11,'Ratio Analysis'!F11,'Ratio Analysis'!G11) -> 33.27413 | E5: ='Master Data (FY26)'!B6*D5/C5 -> 9232.2314 | F5: =MEDIAN('Ratio Analysis'!D12,'Ratio Analysis'!E12,'Ratio Analysis'!F12,'Ratio Analysis'!G12) -> 2.6883544 | G5: ='Master Data (FY26)'!B7*F5/C5 -> 6450.4913 | H5: =AVERAGE(E5,G5)/B5-1 -> -0.2759793 | I5: ='Master Data (FY26)'!B6*'Valuation Justification'!N5/C5 -> 10830.3 | J5: ='Master Data (FY26)'!B7*'Valuation Justification'!O5/C5 -> 10830.3 | K5: =AVERAGE(I5,J5)/B5-1 -> 0
A6: Shree Cement | B6: ='Master Data (FY26)'!C8 -> 21908.95 | C6: ='Master Data (FY26)'!C9 -> 3.6081 | D6: =MEDIAN('Ratio Analysis'!C11,'Ratio Analysis'!E11,'Ratio Analysis'!F11,'Ratio Analysis'!G11) -> 33.209901 | E6: ='Master Data (FY26)'!C6*D6/C6 -> 16095.126 | F6: =MEDIAN('Ratio Analysis'!C12,'Ratio Analysis'!E12,'Ratio Analysis'!F12,'Ratio Analysis'!G12) -> 3.1894708 | G6: ='Master Data (FY26)'!C7*F6/C6 -> 19899.842 | H6: =AVERAGE(E6,G6)/B6-1 -> -0.17853278 | I6: ='Master Data (FY26)'!C6*'Valuation Justification'!N6/C6 -> 19002.038 | J6: ='Master Data (FY26)'!C7*'Valuation Justification'!O6/C6 -> 20904.396 | K6: =AVERAGE(I6,J6)/B6-1 -> -0.08926639
A7: Ambuja | B7: ='Master Data (FY26)'!D8 -> 384.05 | C7: ='Master Data (FY26)'!D9 -> 255.20533 | D7: =MEDIAN('Ratio Analysis'!C11,'Ratio Analysis'!D11,'Ratio Analysis'!F11,'Ratio Analysis'!G11) -> 39.098001 | E7: ='Master Data (FY26)'!D6*D7/C7 -> 724.37034 | F7: =MEDIAN('Ratio Analysis'!C12,'Ratio Analysis'!D12,'Ratio Analysis'!F12,'Ratio Analysis'!G12) -> 4.0125994 | G7: ='Master Data (FY26)'!D7*F7/C7 -> 826.19422 | H7: =AVERAGE(E7,G7)/B7-1 -> 1.0187014 | I7: ='Master Data (FY26)'!D6*'Valuation Justification'!N7/C7 -> 554.21017 | J7: ='Master Data (FY26)'!D7*'Valuation Justification'!O7/C7 -> 605.12211 | K7: =AVERAGE(I7,J7)/B7-1 -> 0.50935071
A8: JK Cement | B8: ='Master Data (FY26)'!E8 -> 5030.3 | C8: ='Master Data (FY26)'!E9 -> 7.7268 | D8: =MEDIAN('Ratio Analysis'!C11,'Ratio Analysis'!D11,'Ratio Analysis'!E11,'Ratio Analysis'!G11) -> 33.209901 | E8: ='Master Data (FY26)'!E6*D8/C8 -> 4265.7367 | F8: =MEDIAN('Ratio Analysis'!C12,'Ratio Analysis'!D12,'Ratio Analysis'!E12,'Ratio Analysis'!G12) -> 2.6883544 | G8: ='Master Data (FY26)'!E7*F8/C8 -> 2421.8041 | H8: =AVERAGE(E8,G8)/B8-1 -> -0.33527416 | I8: ='Master Data (FY26)'!E6*'Valuation Justification'!N8/C8 -> 4839.1592 | J8: ='Master Data (FY26)'!E7*'Valuation Justification'!O8/C8 -> 4378.176 | K8: =AVERAGE(I8,J8)/B8-1 -> -0.083818539
A9: Dalmia Bharat | B9: ='Master Data (FY26)'!F8 -> 1690 | C9: ='Master Data (FY26)'!F9 -> 18.757 | D9: =MEDIAN('Ratio Analysis'!C11,'Ratio Analysis'!D11,'Ratio Analysis'!E11,'Ratio Analysis'!F11) -> 39.098001 | E9: ='Master Data (FY26)'!F6*D9/C9 -> 2412.7492 | F9: =MEDIAN('Ratio Analysis'!C12,'Ratio Analysis'!D12,'Ratio Analysis'!E12,'Ratio Analysis'!F12) -> 4.0125994 | G9: ='Master Data (FY26)'!F7*F9/C9 -> 3846.1654 | H9: =AVERAGE(E9,G9)/B9-1 -> 0.85174988 | I9: ='Master Data (FY26)'!F6*'Valuation Justification'!N9/C9 -> 2051.3746 | J9: ='Master Data (FY26)'!F7*'Valuation Justification'!O9/C9 -> 2768.0827 | K9: =AVERAGE(I9,J9)/B9-1 -> 0.42587494
A11: Columns D to H apply the full peer-median multiple. Columns I to K apply the convergence-adjusted multiple from the Valuation Justification sheet and drive the ratings.

Sheet Valuation Justification
A1: Valuation justification: should each company converge to the peer median?
A2: A discount to the peer median is only expected to close if fundamentals support it. Four equal-weight tests decide how much of the gap closes.
A4: Company | B4: Own P/E | C4: Peer-median P/E (other four) | D4: Premium / (discount) to median | E4: Own P/B | F4: Peer-median P/B (other four) | G4: Test 1: ROE at or above median | H4: Test 2: EBITDA margin at or above median | I4: Test 3: 2Y revenue CAGR at or above median | J4: Test 4: earnings quality (PAT/EBITDA within band) | K4: Fundamentals share (0-1) | L4: Position | M4: Convergence factor | N4: Adjusted P/E (x) | O4: Adjusted P/B (x) | P4: Why (analyst reading)
A5: UltraTech | B5: ='Ratio Analysis'!C11 -> 39.033772 | C5: ='CCA Valuation'!D5 -> 33.27413 | D5: =B5/C5-1 -> 0.17309668 | E5: ='Ratio Analysis'!C12 -> 4.5137158 | F5: ='CCA Valuation'!F5 -> 2.6883544 | G5: =IF(B14>=B$19,1,0) -> 1 | H5: =IF(C14>=C$19,1,0) -> 1 | I5: =IF(D14>=D$19,1,0) -> 1 | J5: =IF(AND(E14>=E$21,E14<=E$22),1,0) -> 1 | K5: =SUM(G5:J5)/4 -> 1 | L5: =IF(C5>B5,"Discount","Premium") -> Premium | M5: =IF(C5>B5,K5,1-K5) -> 0 | N5: =B5+M5*(C5-B5) -> 39.033772 | O5: =E5+M5*(F5-E5) -> 4.5137158 | P5: Premium rests on best-in-set growth, scale and normal earnings quality, so no reversion to the median is assumed.
A6: Shree Cement | B6: ='Ratio Analysis'!D11 -> 45.205862 | C6: ='CCA Valuation'!D6 -> 33.209901 | D6: =B6/C6-1 -> 0.3612164 | E6: ='Ratio Analysis'!D12 -> 3.511483 | F6: ='CCA Valuation'!F6 -> 3.1894708 | G6: =IF(B15>=B$19,1,0) -> 0 | H6: =IF(C15>=C$19,1,0) -> 1 | I6: =IF(D15>=D$19,1,0) -> 0 | J6: =IF(AND(E15>=E$21,E15<=E$22),1,0) -> 1 | K6: =SUM(G6:J6)/4 -> 0.5 | L6: =IF(C6>B6,"Discount","Premium") -> Premium | M6: =IF(C6>B6,K6,1-K6) -> 0.5 | N6: =B6+M6*(C6-B6) -> 39.207881 | O6: =E6+M6*(F6-E6) -> 3.3504769 | P6: Top margin supports some premium, but ROE and growth lag peers, so half of the premium is assumed to erode.
A7: Ambuja | B7: ='Ratio Analysis'!E11 -> 20.729158 | C7: ='CCA Valuation'!D7 -> 39.098001 | D7: =B7/C7-1 -> -0.4698154 | E7: ='Ratio Analysis'!E12 -> 1.8652258 | F7: ='CCA Valuation'!F7 -> 4.0125994 | G7: =IF(B16>=B$19,1,0) -> 1 | H7: =IF(C16>=C$19,1,0) -> 0 | I7: =IF(D16>=D$19,1,0) -> 1 | J7: =IF(AND(E16>=E$21,E16<=E$22),1,0) -> 0 | K7: =SUM(G7:J7)/4 -> 0.5 | L7: =IF(C7>B7,"Discount","Premium") -> Discount | M7: =IF(C7>B7,K7,1-K7) -> 0.5 | N7: =B7+M7*(C7-B7) -> 29.91358 | O7: =E7+M7*(F7-E7) -> 2.9389126 | P7: Discount is partly deserved: lowest EBITDA margin and a profit base with one-offs (earnings-quality test fails), so only half the gap to the median is assumed to close.
A8: JK Cement | B8: ='Ratio Analysis'!F11 -> 39.16223 | C8: ='CCA Valuation'!D8 -> 33.209901 | D8: =B8/C8-1 -> 0.17923358 | E8: ='Ratio Analysis'!F12 -> 5.5839485 | F8: ='CCA Valuation'!F8 -> 2.6883544 | G8: =IF(B17>=B$19,1,0) -> 1 | H8: =IF(C17>=C$19,1,0) -> 0 | I8: =IF(D17>=D$19,1,0) -> 1 | J8: =IF(AND(E17>=E$21,E17<=E$22),1,0) -> 1 | K8: =SUM(G8:J8)/4 -> 0.75 | L8: =IF(C8>B8,"Discount","Premium") -> Premium | M8: =IF(C8>B8,K8,1-K8) -> 0.25 | N8: =B8+M8*(C8-B8) -> 37.674148 | O8: =E8+M8*(F8-E8) -> 4.86005 | P8: Premium is partly backed by ROE and growth, but debt is the highest in the set; a quarter of the premium is assumed to erode.
A9: Dalmia Bharat | B9: ='Ratio Analysis'!G11 -> 27.38603 | C9: ='CCA Valuation'!D9 -> 39.098001 | D9: =B9/C9-1 -> -0.29955421 | E9: ='Ratio Analysis'!G12 -> 1.7631309 | F9: ='CCA Valuation'!F9 -> 4.0125994 | G9: =IF(B18>=B$19,1,0) -> 0 | H9: =IF(C18>=C$19,1,0) -> 1 | I9: =IF(D18>=D$19,1,0) -> 0 | J9: =IF(AND(E18>=E$21,E18<=E$22),1,0) -> 1 | K9: =SUM(G9:J9)/4 -> 0.5 | L9: =IF(C9>B9,"Discount","Premium") -> Discount | M9: =IF(C9>B9,K9,1-K9) -> 0.5 | N9: =B9+M9*(C9-B9) -> 33.242016 | O9: =E9+M9*(F9-E9) -> 2.8878651 | P9: Discount reflects flat revenue and a weaker ROE; margins are strong and leverage moderate, so half the gap is assumed to close.
A11: Rule: if the company trades at a discount, the share of the gap that closes equals its fundamentals share; if it trades at a premium, the share of the premium that erodes is 1 minus its fundamentals share. Adjusted multiple = own multiple + factor x (peer median - own multiple).
A13: Fundamentals test data | B13: ROE | C13: EBITDA margin | D13: 2Y revenue CAGR | E13: PAT / EBITDA (FY26)
A14: UltraTech | B14: ='Ratio Analysis'!C13 -> 0.11563617 | C14: ='Ratio Analysis'!C8 -> 0.19229366 | D14: ='Ratio Analysis'!C6 -> 0.11725402 | E14: ='Master Data (FY26)'!B6/'Master Data (FY26)'!B5 -> 0.47976169
A15: Shree Cement | B15: ='Ratio Analysis'!D13 -> 0.077677603 | C15: ='Ratio Analysis'!D8 -> 0.22145327 | D15: ='Ratio Analysis'!D6 -> 0.013138433 | E15: ='Master Data (FY26)'!C6/'Master Data (FY26)'!C5 -> 0.37702889
A16: Ambuja | B16: ='Ratio Analysis'!E13 -> 0.089980781 | C16: ='Ratio Analysis'!E8 -> 0.15678736 | D16: ='Ratio Analysis'!E6 -> 0.10727649 | E16: ='Master Data (FY26)'!D6/'Master Data (FY26)'!D5 -> 0.74175988
A17: JK Cement | B17: ='Ratio Analysis'!F13 -> 0.14258505 | C17: ='Ratio Analysis'!F8 -> 0.17300307 | D17: ='Ratio Analysis'!F6 -> 0.089706868 | E17: ='Master Data (FY26)'!E6/'Master Data (FY26)'!E5 -> 0.41806655
A18: Dalmia Bharat | B18: ='Ratio Analysis'!G13 -> 0.064380666 | C18: ='Ratio Analysis'!G8 -> 0.20825453 | D18: ='Ratio Analysis'!G6 -> 0.0038385249 | E18: ='Master Data (FY26)'!F6/'Master Data (FY26)'!F5 -> 0.37544599
A19: Median of five | B19: =MEDIAN(B14:B18) -> 0.089980781 | C19: =MEDIAN(C14:C18) -> 0.19229366 | D19: =MEDIAN(D14:D18) -> 0.089706868 | E19: =MEDIAN(E14:E18) -> 0.41806655
A20: Earnings-quality band (+/- of median) | B20: 0.25
A21: Band low | E21: =E19*(1-B20) -> 0.31354992
A22: Band high | E22: =E19*(1+B20) -> 0.52258319
A25: Forward upside on FY28E EPS | B25: No convergence (hold current P/E) | C25: Rule-based (adjusted) | D25: Full convergence (peer median)
A26: UltraTech | B26: ='Forward & Historical Valuation'!B16*B5/'CCA Valuation'!B5-1 -> 0.1885301 | C26: ='Forward & Historical Valuation'!B16*N5/'CCA Valuation'!B5-1 -> 0.1885301 | D26: ='Forward & Historical Valuation'!B16*C5/'CCA Valuation'!B5-1 -> 0.013156137
A27: Shree Cement | B27: ='Forward & Historical Valuation'!B17*B6/'CCA Valuation'!B6-1 -> 0.15936082 | C27: ='Forward & Historical Valuation'!B17*N6/'CCA Valuation'!B6-1 -> 0.0055351188 | D27: ='Forward & Historical Valuation'!B17*C6/'CCA Valuation'!B6-1 -> -0.14829058
A28: Ambuja | B28: ='Forward & Historical Valuation'!B18*B7/'CCA Valuation'!B7-1 -> 0.038155449 | C28: ='Forward & Historical Valuation'!B18*N7/'CCA Valuation'!B7-1 -> 0.49812865 | D28: ='Forward & Historical Valuation'!B18*C7/'CCA Valuation'!B7-1 -> 0.95810185
A29: JK Cement | B29: ='Forward & Historical Valuation'!B19*B8/'CCA Valuation'!B8-1 -> 0.20320551 | C29: ='Forward & Historical Valuation'!B19*N8/'CCA Valuation'!B8-1 -> 0.15748623 | D29: ='Forward & Historical Valuation'!B19*C8/'CCA Valuation'!B8-1 -> 0.0203284
A30: Dalmia Bharat | B30: ='Forward & Historical Valuation'!B20*B9/'CCA Valuation'!B9-1 -> 0.099084771 | C30: ='Forward & Historical Valuation'!B20*N9/'CCA Valuation'!B9-1 -> 0.3341033 | D30: ='Forward & Historical Valuation'!B20*C9/'CCA Valuation'!B9-1 -> 0.56912182

Sheet Dashboard
A1: Dashboard - FY26 Peer Comparison
A2: Green = best in peer set, red = weakest
A3: Metric | B3: UltraTech | C3: Shree Cement | D3: Ambuja | E3: JK Cement | F3: Dalmia Bharat
A4: Revenue (Rs Cr) | B4: ='Ratio Analysis'!C4 -> 88511.5 | C4: ='Ratio Analysis'!D4 -> 20943.47 | D4: ='Ratio Analysis'!E4 -> 40655.7 | E4: ='Ratio Analysis'!F4 -> 13722.3 | F4: ='Ratio Analysis'!G4 -> 14804
A5: FY26 Revenue Growth | B5: ='Ratio Analysis'!C5 -> 0.16531345 | C5: ='Ratio Analysis'!D5 -> 0.086120139 | D5: ='Ratio Analysis'!E5 -> 0.15053316 | E5: ='Ratio Analysis'!F5 -> 0.15515841 | F5: ='Ratio Analysis'!G5 -> 0.058941345
A6: 2Y Revenue CAGR | B6: ='Ratio Analysis'!C6 -> 0.11725402 | C6: ='Ratio Analysis'!D6 -> 0.013138433 | D6: ='Ratio Analysis'!E6 -> 0.10727649 | E6: ='Ratio Analysis'!F6 -> 0.089706868 | F6: ='Ratio Analysis'!G6 -> 0.0038385249
A7: EBITDA Margin | B7: ='Ratio Analysis'!C8 -> 0.19229366 | C7: ='Ratio Analysis'!D8 -> 0.22145327 | D7: ='Ratio Analysis'!E8 -> 0.15678736 | E7: ='Ratio Analysis'!F8 -> 0.17300307 | F7: ='Ratio Analysis'!G8 -> 0.20825453
A8: Net Margin | B8: ='Ratio Analysis'!C10 -> 0.092255131 | C8: ='Ratio Analysis'!D10 -> 0.083494282 | D8: ='Ratio Analysis'!E10 -> 0.11629858 | E8: ='Ratio Analysis'!F10 -> 0.072326797 | F8: ='Ratio Analysis'!G10 -> 0.078188327
A9: ROE | B9: ='Ratio Analysis'!C13 -> 0.11563617 | C9: ='Ratio Analysis'!D13 -> 0.077677603 | D9: ='Ratio Analysis'!E13 -> 0.089980781 | E9: ='Ratio Analysis'!F13 -> 0.14258505 | F9: ='Ratio Analysis'!G13 -> 0.064380666
A10: Debt / Equity | B10: ='Ratio Analysis'!C14 -> 0.33640336 | C10: ='Ratio Analysis'!D14 -> 0.082978831 | D10: ='Ratio Analysis'!E14 -> 0.016480554 | E10: ='Ratio Analysis'!F14 -> 0.87 | F10: ='Ratio Analysis'!G14 -> 0.41314867
A11: P/E Ratio | B11: ='Ratio Analysis'!C11 -> 39.033772 | C11: ='Ratio Analysis'!D11 -> 45.205862 | D11: ='Ratio Analysis'!E11 -> 20.729158 | E11: ='Ratio Analysis'!F11 -> 39.16223 | F11: ='Ratio Analysis'!G11 -> 27.38603
A12: P/B Ratio | B12: ='Ratio Analysis'!C12 -> 4.5137158 | C12: ='Ratio Analysis'!D12 -> 3.511483 | D12: ='Ratio Analysis'!E12 -> 1.8652258 | E12: ='Ratio Analysis'!F12 -> 5.5839485 | F12: ='Ratio Analysis'!G12 -> 1.7631309

Sheet Qualitative Analysis
A1: Qualitative Analysis - Positioning, Catalysts, Risks & Watch Triggers
A3: Company | B3: Scale/Growth Score (1-5) | C3: Cost & Balance-Sheet Score (1-5) | D3: Positioning | E3: Key growth catalyst | F3: Key risk | G3: Watch trigger - Margin | H3: Watch trigger - Growth | I3: Watch trigger - Valuation / Leverage
A4: UltraTech | B4: 5 | C4: 4 | D4: Largest producer, 200.1 MTPA, pan-India footprint | E4: Domestic capacity to exceed 240 MTPA by FY28 | F4: Premium valuation relative to peers; exposed to fuel and freight inflation | G4: ="EBITDA margin below ~"&TEXT(0.18,"0.0%")&" (FY26: "&TEXT('Ratio Analysis'!C8,"0.0%")&")" -> EBITDA margin below ~18.0% (FY26: 19.2%) | H4: ="Revenue growth below ~"&TEXT(0.09,"0%")&" (FY26: "&TEXT('Ratio Analysis'!C5,"0.0%")&")" -> Revenue growth below ~9% (FY26: 16.5%) | I4: P/E above ~45x without EPS upgrades
A5: Shree Cement | B5: 3 | C5: 5 | D5: Highest EBITDA margin in the peer set; 69.3 MTPA, strong in North India | E5: New 3.0 MTPA line at Jaitaran (Feb-2026); target 80+ MTPA | F5: Slow revenue growth; richest P/E in the set | G5: ="EBITDA margin below ~"&TEXT(0.21,"0.0%")&" (FY26: "&TEXT('Ratio Analysis'!D8,"0.0%")&")" -> EBITDA margin below ~21.0% (FY26: 22.1%) | H5: ="Revenue growth below ~"&TEXT(0.05,"0%")&" (FY26: "&TEXT('Ratio Analysis'!D5,"0.0%")&")" -> Revenue growth below ~5% (FY26: 8.6%) | I5: P/E stays above ~45x with flat earnings
A6: Ambuja | B6: 4 | C6: 3 | D6: 109 MTPA across Ambuja and ACC; almost debt free | E6: Target 119 MTPA by end FY27; integration of acquired capacity | F6: Lowest EBITDA margin in the set; FY26 profit includes non-recurring items | G6: ="EBITDA margin below ~"&TEXT(0.145,"0.0%")&" (FY26: "&TEXT('Ratio Analysis'!E8,"0.0%")&")" -> EBITDA margin below ~14.5% (FY26: 15.7%) | H6: ="Revenue growth below ~"&TEXT(0.1,"0%")&" (FY26: "&TEXT('Ratio Analysis'!E5,"0.0%")&")" -> Revenue growth below ~10% (FY26: 15.1%) | I6: ROE stays below ~9% as equity grows
A7: JK Cement | B7: 4 | C7: 2 | D7: 32.26 MTPA grey cement plus white cement and wall putty | E7: Plan to reach about 50 MTPA by FY30 | F7: Highest debt/equity in the set; richest P/B | G7: ="EBITDA margin below ~"&TEXT(0.16,"0.0%")&" (FY26: "&TEXT('Ratio Analysis'!F8,"0.0%")&")" -> EBITDA margin below ~16.0% (FY26: 17.3%) | H7: ="Revenue growth below ~"&TEXT(0.1,"0%")&" (FY26: "&TEXT('Ratio Analysis'!F5,"0.0%")&")" -> Revenue growth below ~10% (FY26: 15.5%) | I7: Debt/Equity above ~1.0x
A8: Dalmia Bharat | B8: 3 | C8: 4 | D8: 54.7 MTPA after acquisition; South and East focus | E8: Target about 67 MTPA by FY28 | F8: Southern capacity overhang (ICRA); flat revenue over two years | G8: ="EBITDA margin below ~"&TEXT(0.18,"0.0%")&" (FY26: "&TEXT('Ratio Analysis'!G8,"0.0%")&")" -> EBITDA margin below ~18.0% (FY26: 20.8%) | H8: ="Revenue growth below ~"&TEXT(0.04,"0%")&" (FY26: "&TEXT('Ratio Analysis'!G5,"0.0%")&")" -> Revenue growth below ~4% (FY26: 5.9%) | I8: Net debt/EBITDA above ~1.0x during expansion
A10: Scoring: 5 = clearly leading; 3 = average; 1 = weak. Analyst judgement, informed by FY26 disclosures.

Sheet Cost & Risk Assessment
A1: Cost structure and risk assessment
A2: Part A links to sourced sector data. Part B scores are analyst judgement (1 = low risk, 5 = high risk) except balance-sheet risk, which is formula-driven from Debt/Equity.
A3: A. Sector cost structure (mid-points)
A4: Item | B4: Mid-point | C4: Reading
A5: Power and fuel share of total cost | B5: ='Macro & Sector Data'!D21 -> 0.27 | C5: Largest controllable cost; coal and petcoke driven
A6: Power, fuel and selling share of opex | B6: ='Macro & Sector Data'!D22 -> 0.525 | C6: Fuel plus freight and packaging decide margins
A7: Imported petcoke share of fuel | B7: ='Macro & Sector Data'!D23 -> 0.55 | C7: Exposure to crude and rupee moves
A8: Power and fuel cost growth FY27E | B8: ='Macro & Sector Data'!D24 -> 0.11 | C8: Main source of FY27 margin pressure
A9: Total cost growth FY27E | B9: ='Macro & Sector Data'!D26 -> 0.05 | C9: Cost growth above realisation growth compresses margins
A10: Implied change in OPBITDA per tonne FY27E | B10: ='Macro & Sector Data'!D37 -> 0 | C10: ICRA outlook
A13: B. Company risk matrix
A14: Company | B14: Energy and fuel exposure | C14: Logistics and geographic concentration | D14: Regulatory and environmental | E14: Balance-sheet risk (from D/E) | F14: Composite risk | G14: Risk rank (1 = lowest) | H14: Rationale (analyst view)
A15: UltraTech | B15: 3 | C15: 1 | D15: 3 | E15: =IF('Ratio Analysis'!C14<$B$23,1,IF('Ratio Analysis'!C14<$B$24,2,IF('Ratio Analysis'!C14<$B$25,3,IF('Ratio Analysis'!C14<$B$26,4,5)))) -> 3 | F15: =AVERAGE(B15:E15) -> 2.5 | G15: =RANK(F15,$F$15:$F$19,1) -> 3 | H15: Pan-India network spreads regional risk; largest fuel buyer so cost swings matter; moderate leverage.
A16: Shree Cement | B16: 2 | C16: 3 | D16: 3 | E16: =IF('Ratio Analysis'!D14<$B$23,1,IF('Ratio Analysis'!D14<$B$24,2,IF('Ratio Analysis'!D14<$B$25,3,IF('Ratio Analysis'!D14<$B$26,4,5)))) -> 1 | F16: =AVERAGE(B16:E16) -> 2.25 | G16: =RANK(F16,$F$15:$F$19,1) -> 1 | H16: North-led footprint with above-average utilisation, strong cost record; almost no debt; growth is slow.
A17: Ambuja | B17: 3 | C17: 2 | D17: 3 | E17: =IF('Ratio Analysis'!E14<$B$23,1,IF('Ratio Analysis'!E14<$B$24,2,IF('Ratio Analysis'!E14<$B$25,3,IF('Ratio Analysis'!E14<$B$26,4,5)))) -> 1 | F17: =AVERAGE(B17:E17) -> 2.25 | G17: =RANK(F17,$F$15:$F$19,1) -> 1 | H17: Spread across regions after acquisitions; integration risk; nearly debt free.
A18: JK Cement | B18: 3 | C18: 3 | D18: 3 | E18: =IF('Ratio Analysis'!F14<$B$23,1,IF('Ratio Analysis'!F14<$B$24,2,IF('Ratio Analysis'!F14<$B$25,3,IF('Ratio Analysis'!F14<$B$26,4,5)))) -> 4 | F18: =AVERAGE(B18:E18) -> 3.25 | G18: =RANK(F18,$F$15:$F$19,1) -> 4 | H18: Mid-size with north, central and south plants; highest leverage in the set.
A19: Dalmia Bharat | B19: 3 | C19: 4 | D19: 3 | E19: =IF('Ratio Analysis'!G14<$B$23,1,IF('Ratio Analysis'!G14<$B$24,2,IF('Ratio Analysis'!G14<$B$25,3,IF('Ratio Analysis'!G14<$B$26,4,5)))) -> 3 | F19: =AVERAGE(B19:E19) -> 3.25 | G19: =RANK(F19,$F$15:$F$19,1) -> 4 | H19: South and East focus where capacity overhang keeps utilisation and prices weaker (ICRA, Ind-Ra); modest leverage.
A21: Balance-sheet risk score thresholds (Debt/Equity)
A23: Score 1 if D/E below | B23: 0.1
A24: Score 2 if D/E below | B24: 0.3
A25: Score 3 if D/E below | B25: 0.6
A26: Score 4 if D/E below | B26: 0.9

Sheet Investment Scorecard
A1: Investment Scorecard - Quantitative Screening
J2: Rank scores (5 = best of 5)
A3: Metric | B3: Weight | C3: UltraTech | D3: Shree Cement | E3: Ambuja | F3: JK Cement | G3: Dalmia Bharat | H3: Direction | J3: UltraTech | K3: Shree Cement | L3: Ambuja | M3: JK Cement | N3: Dalmia Bharat
A4: 2Y Revenue CAGR | B4: 0.2 | C4: ='Ratio Analysis'!C6 -> 0.11725402 | D4: ='Ratio Analysis'!D6 -> 0.013138433 | E4: ='Ratio Analysis'!E6 -> 0.10727649 | F4: ='Ratio Analysis'!F6 -> 0.089706868 | G4: ='Ratio Analysis'!G6 -> 0.0038385249 | H4: Higher is better | J4: =6-RANK(C4,$C4:$G4,0) -> 5 | K4: =6-RANK(D4,$C4:$G4,0) -> 2 | L4: =6-RANK(E4,$C4:$G4,0) -> 4 | M4: =6-RANK(F4,$C4:$G4,0) -> 3 | N4: =6-RANK(G4,$C4:$G4,0) -> 1
A5: EBITDA Margin | B5: 0.2 | C5: ='Ratio Analysis'!C8 -> 0.19229366 | D5: ='Ratio Analysis'!D8 -> 0.22145327 | E5: ='Ratio Analysis'!E8 -> 0.15678736 | F5: ='Ratio Analysis'!F8 -> 0.17300307 | G5: ='Ratio Analysis'!G8 -> 0.20825453 | H5: Higher is better | J5: =6-RANK(C5,$C5:$G5,0) -> 3 | K5: =6-RANK(D5,$C5:$G5,0) -> 5 | L5: =6-RANK(E5,$C5:$G5,0) -> 1 | M5: =6-RANK(F5,$C5:$G5,0) -> 2 | N5: =6-RANK(G5,$C5:$G5,0) -> 4
A6: ROE | B6: 0.15 | C6: ='Ratio Analysis'!C13 -> 0.11563617 | D6: ='Ratio Analysis'!D13 -> 0.077677603 | E6: ='Ratio Analysis'!E13 -> 0.089980781 | F6: ='Ratio Analysis'!F13 -> 0.14258505 | G6: ='Ratio Analysis'!G13 -> 0.064380666 | H6: Higher is better | J6: =6-RANK(C6,$C6:$G6,0) -> 4 | K6: =6-RANK(D6,$C6:$G6,0) -> 2 | L6: =6-RANK(E6,$C6:$G6,0) -> 3 | M6: =6-RANK(F6,$C6:$G6,0) -> 5 | N6: =6-RANK(G6,$C6:$G6,0) -> 1
A7: Debt / Equity | B7: 0.15 | C7: ='Ratio Analysis'!C14 -> 0.33640336 | D7: ='Ratio Analysis'!D14 -> 0.082978831 | E7: ='Ratio Analysis'!E14 -> 0.016480554 | F7: ='Ratio Analysis'!F14 -> 0.87 | G7: ='Ratio Analysis'!G14 -> 0.41314867 | H7: Lower is better | J7: =6-RANK(C7,$C7:$G7,1) -> 3 | K7: =6-RANK(D7,$C7:$G7,1) -> 4 | L7: =6-RANK(E7,$C7:$G7,1) -> 5 | M7: =6-RANK(F7,$C7:$G7,1) -> 1 | N7: =6-RANK(G7,$C7:$G7,1) -> 2
A8: P/E Ratio | B8: 0.2 | C8: ='Ratio Analysis'!C11 -> 39.033772 | D8: ='Ratio Analysis'!D11 -> 45.205862 | E8: ='Ratio Analysis'!E11 -> 20.729158 | F8: ='Ratio Analysis'!F11 -> 39.16223 | G8: ='Ratio Analysis'!G11 -> 27.38603 | H8: Lower is better | J8: =6-RANK(C8,$C8:$G8,1) -> 3 | K8: =6-RANK(D8,$C8:$G8,1) -> 1 | L8: =6-RANK(E8,$C8:$G8,1) -> 5 | M8: =6-RANK(F8,$C8:$G8,1) -> 2 | N8: =6-RANK(G8,$C8:$G8,1) -> 4
A9: P/B Ratio | B9: 0.1 | C9: ='Ratio Analysis'!C12 -> 4.5137158 | D9: ='Ratio Analysis'!D12 -> 3.511483 | E9: ='Ratio Analysis'!E12 -> 1.8652258 | F9: ='Ratio Analysis'!F12 -> 5.5839485 | G9: ='Ratio Analysis'!G12 -> 1.7631309 | H9: Lower is better | J9: =6-RANK(C9,$C9:$G9,1) -> 2 | K9: =6-RANK(D9,$C9:$G9,1) -> 3 | L9: =6-RANK(E9,$C9:$G9,1) -> 4 | M9: =6-RANK(F9,$C9:$G9,1) -> 1 | N9: =6-RANK(G9,$C9:$G9,1) -> 5
A10: Weighted Score | C10: =SUMPRODUCT($B$4:$B$9,J$4:J$9) -> 3.45 | D10: =SUMPRODUCT($B$4:$B$9,K$4:K$9) -> 2.8 | E10: =SUMPRODUCT($B$4:$B$9,L$4:L$9) -> 3.6 | F10: =SUMPRODUCT($B$4:$B$9,M$4:M$9) -> 2.4 | G10: =SUMPRODUCT($B$4:$B$9,N$4:N$9) -> 2.75
A12: Weight Check | B12: =SUM(B4:B9) -> 1
A13: Model Leader | B13: =INDEX(C3:G3,1,MATCH(MAX(C10:G10),C10:G10,0)) -> Ambuja
A14: Leader / Score | B14: =B13&" | "&TEXT(MAX(C10:G10),"0.00")&" / 5.00" -> Ambuja | 3.60 / 5.00
A15: Rank | C15: =RANK(C10,$C$10:$G$10,0) -> 2 | D15: =RANK(D10,$C$10:$G$10,0) -> 3 | E15: =RANK(E10,$C$10:$G$10,0) -> 1 | F15: =RANK(F10,$C$10:$G$10,0) -> 5 | G15: =RANK(G10,$C$10:$G$10,0) -> 4

Sheet Scorecard Sensitivity
A1: Investment Scorecard - Weight Sensitivity
A2: Does the ranking survive reasonable alternative weightings?
A4: Metric | B4: Base Case | C4: Growth-Tilted | D4: Quality-Tilted | E4: Valuation-Tilted | F4: Direction
A5: 2Y Revenue CAGR | B5: ='Investment Scorecard'!B4 -> 0.2 | C5: 0.35 | D5: 0.1 | E5: 0.1 | F5: Higher is better
A6: EBITDA Margin | B6: ='Investment Scorecard'!B5 -> 0.2 | C6: 0.15 | D6: 0.25 | E6: 0.15 | F6: Higher is better
A7: ROE | B7: ='Investment Scorecard'!B6 -> 0.15 | C7: 0.1 | D7: 0.25 | E7: 0.1 | F7: Higher is better
A8: Debt / Equity | B8: ='Investment Scorecard'!B7 -> 0.15 | C8: 0.1 | D8: 0.15 | E8: 0.1 | F8: Lower is better
A9: P/E Ratio | B9: ='Investment Scorecard'!B8 -> 0.2 | C9: 0.2 | D9: 0.15 | E9: 0.35 | F9: Lower is better
A10: P/B Ratio | B10: ='Investment Scorecard'!B9 -> 0.1 | C10: 0.1 | D10: 0.1 | E10: 0.2 | F10: Lower is better
A11: Weight Check | B11: =SUM(B5:B10) -> 1 | C11: =SUM(C5:C10) -> 1 | D11: =SUM(D5:D10) -> 1 | E11: =SUM(E5:E10) -> 1
A14: Company | B14: Base Case | C14: Growth-Tilted | D14: Quality-Tilted | E14: Valuation-Tilted | F14: Rank (Base) | G14: Best rank across scenarios | H14: Worst rank across scenarios
A15: UltraTech | B15: =SUMPRODUCT($B$5:$B$10,'Investment Scorecard'!J4:J9) -> 3.45 | C15: =SUMPRODUCT($C$5:$C$10,'Investment Scorecard'!J4:J9) -> 3.7 | D15: =SUMPRODUCT($D$5:$D$10,'Investment Scorecard'!J4:J9) -> 3.35 | E15: =SUMPRODUCT($E$5:$E$10,'Investment Scorecard'!J4:J9) -> 3.1 | F15: =RANK(B15,$B$15:$B$19,0) -> 2 | G15: =MIN(RANK(B15,$B$15:$B$19,0),RANK(C15,$C$15:$C$19,0),RANK(D15,$D$15:$D$19,0),RANK(E15,$E$15:$E$19,0)) -> 1 | H15: =MAX(RANK(B15,$B$15:$B$19,0),RANK(C15,$C$15:$C$19,0),RANK(D15,$D$15:$D$19,0),RANK(E15,$E$15:$E$19,0)) -> 3
A16: Shree Cement | B16: =SUMPRODUCT($B$5:$B$10,'Investment Scorecard'!K4:K9) -> 2.8 | C16: =SUMPRODUCT($C$5:$C$10,'Investment Scorecard'!K4:K9) -> 2.55 | D16: =SUMPRODUCT($D$5:$D$10,'Investment Scorecard'!K4:K9) -> 3 | E16: =SUMPRODUCT($E$5:$E$10,'Investment Scorecard'!K4:K9) -> 2.5 | F16: =RANK(B16,$B$15:$B$19,0) -> 3 | G16: =MIN(RANK(B16,$B$15:$B$19,0),RANK(C16,$C$15:$C$19,0),RANK(D16,$D$15:$D$19,0),RANK(E16,$E$15:$E$19,0)) -> 3 | H16: =MAX(RANK(B16,$B$15:$B$19,0),RANK(C16,$C$15:$C$19,0),RANK(D16,$D$15:$D$19,0),RANK(E16,$E$15:$E$19,0)) -> 4
A17: Ambuja | B17: =SUMPRODUCT($B$5:$B$10,'Investment Scorecard'!L4:L9) -> 3.6 | C17: =SUMPRODUCT($C$5:$C$10,'Investment Scorecard'!L4:L9) -> 3.75 | D17: =SUMPRODUCT($D$5:$D$10,'Investment Scorecard'!L4:L9) -> 3.3 | E17: =SUMPRODUCT($E$5:$E$10,'Investment Scorecard'!L4:L9) -> 3.9 | F17: =RANK(B17,$B$15:$B$19,0) -> 1 | G17: =MIN(RANK(B17,$B$15:$B$19,0),RANK(C17,$C$15:$C$19,0),RANK(D17,$D$15:$D$19,0),RANK(E17,$E$15:$E$19,0)) -> 1 | H17: =MAX(RANK(B17,$B$15:$B$19,0),RANK(C17,$C$15:$C$19,0),RANK(D17,$D$15:$D$19,0),RANK(E17,$E$15:$E$19,0)) -> 2
A18: JK Cement | B18: =SUMPRODUCT($B$5:$B$10,'Investment Scorecard'!M4:M9) -> 2.4 | C18: =SUMPRODUCT($C$5:$C$10,'Investment Scorecard'!M4:M9) -> 2.45 | D18: =SUMPRODUCT($D$5:$D$10,'Investment Scorecard'!M4:M9) -> 2.6 | E18: =SUMPRODUCT($E$5:$E$10,'Investment Scorecard'!M4:M9) -> 2.1 | F18: =RANK(B18,$B$15:$B$19,0) -> 5 | G18: =MIN(RANK(B18,$B$15:$B$19,0),RANK(C18,$C$15:$C$19,0),RANK(D18,$D$15:$D$19,0),RANK(E18,$E$15:$E$19,0)) -> 5 | H18: =MAX(RANK(B18,$B$15:$B$19,0),RANK(C18,$C$15:$C$19,0),RANK(D18,$D$15:$D$19,0),RANK(E18,$E$15:$E$19,0)) -> 5
A19: Dalmia Bharat | B19: =SUMPRODUCT($B$5:$B$10,'Investment Scorecard'!N4:N9) -> 2.75 | C19: =SUMPRODUCT($C$5:$C$10,'Investment Scorecard'!N4:N9) -> 2.55 | D19: =SUMPRODUCT($D$5:$D$10,'Investment Scorecard'!N4:N9) -> 2.75 | E19: =SUMPRODUCT($E$5:$E$10,'Investment Scorecard'!N4:N9) -> 3.4 | F19: =RANK(B19,$B$15:$B$19,0) -> 4 | G19: =MIN(RANK(B19,$B$15:$B$19,0),RANK(C19,$C$15:$C$19,0),RANK(D19,$D$15:$D$19,0),RANK(E19,$E$15:$E$19,0)) -> 2 | H19: =MAX(RANK(B19,$B$15:$B$19,0),RANK(C19,$C$15:$C$19,0),RANK(D19,$D$15:$D$19,0),RANK(E19,$E$15:$E$19,0)) -> 4
A21: Scenario Leader
A22: Base Case | B22: =INDEX($A$15:$A$19,MATCH(MAX(B15:B19),B15:B19,0)) -> Ambuja
A23: Growth-Tilted | B23: =INDEX($A$15:$A$19,MATCH(MAX(C15:C19),C15:C19,0)) -> Ambuja
A24: Quality-Tilted | B24: =INDEX($A$15:$A$19,MATCH(MAX(D15:D19),D15:D19,0)) -> UltraTech
A25: Valuation-Tilted | B25: =INDEX($A$15:$A$19,MATCH(MAX(E15:E19),E15:E19,0)) -> Ambuja

Sheet FY27-28E Assumptions
A1: FY27E / FY28E Forward Operating Assumptions
A2: Analyst assumptions (not company guidance). FY27E reflects the sourced sector outlook: volumes +6-7%, prices +2-4%, EBITDA margin down 150-200 bps (Crisil) as fuel and freight rise; partial recovery assumed in FY28E.
A4: Company | B4: FY26 Revenue Growth (actual) | C4: FY27E Revenue Growth | D4: FY28E Revenue Growth | E4: FY27E EBITDA Margin | F4: FY28E EBITDA Margin | G4: FY27E Net Margin | H4: FY28E Net Margin
A5: UltraTech | B5: ='Master Data (FY26)'!B14 -> 0.16531345 | C5: 0.12 | D5: 0.1 | E5: 0.182 | F5: 0.188 | G5: 0.085 | H5: 0.089
A6: Shree Cement | B6: ='Master Data (FY26)'!C14 -> 0.086120139 | C6: 0.1 | D6: 0.1 | E6: 0.21 | F6: 0.215 | G6: 0.076 | H6: 0.08
A7: Ambuja | B7: ='Master Data (FY26)'!D14 -> 0.15053316 | C7: 0.12 | D7: 0.1 | E7: 0.148 | F7: 0.155 | G7: 0.095 | H7: 0.098
A8: JK Cement | B8: ='Master Data (FY26)'!E14 -> 0.15515841 | C8: 0.12 | D8: 0.11 | E8: 0.163 | F8: 0.169 | G8: 0.066 | H8: 0.07
A9: Dalmia Bharat | B9: ='Master Data (FY26)'!F14 -> 0.058941345 | C9: 0.09 | D9: 0.08 | E9: 0.19 | F9: 0.195 | G9: 0.07 | H9: 0.073
A11: Projected Financials & Forward Multiples
A12: Company | B12: FY27E Revenue (Rs Cr) | C12: FY28E Revenue (Rs Cr) | D12: FY27E EBITDA (Rs Cr) | E12: FY28E EBITDA (Rs Cr) | F12: FY27E PAT (Rs Cr) | G12: FY28E PAT (Rs Cr) | H12: FY27E EPS (Rs) | I12: FY28E EPS (Rs) | J12: FY27E P/E (x, at CMP) | K12: FY28E P/E (x, at CMP)
A13: UltraTech | B13: ='Master Data (FY26)'!B4*(1+C5) -> 99132.88 | C13: =B13*(1+D5) -> 109046.17 | D13: =B13*E5 -> 18042.184 | E13: =C13*F5 -> 20500.68 | F13: =B13*G5 -> 8426.2948 | G13: =C13*H5 -> 9705.109 | H13: =F13/'CCA Valuation'!C5 -> 286.31651 | I13: =G13/'CCA Valuation'!C5 -> 329.76925 | J13: ='Master Data (FY26)'!B8/H13 -> 37.826321 | K13: ='Master Data (FY26)'!B8/I13 -> 32.842056
A14: Shree Cement | B14: ='Master Data (FY26)'!C4*(1+C6) -> 23037.817 | C14: =B14*(1+D6) -> 25341.599 | D14: =B14*E6 -> 4837.9416 | E14: =C14*F6 -> 5448.4437 | F14: =B14*G6 -> 1750.8741 | G14: =C14*H6 -> 2027.3279 | H14: =F14/'CCA Valuation'!C6 -> 485.26207 | I14: =G14/'CCA Valuation'!C6 -> 561.8824 | J14: ='Master Data (FY26)'!C8/H14 -> 45.148696 | K14: ='Master Data (FY26)'!C8/I14 -> 38.992056
A15: Ambuja | B15: ='Master Data (FY26)'!D4*(1+C7) -> 45534.384 | C15: =B15*(1+D7) -> 50087.822 | D15: =B15*E7 -> 6739.0888 | E15: =C15*F7 -> 7763.6125 | F15: =B15*G7 -> 4325.7665 | G15: =C15*H7 -> 4908.6066 | H15: =F15/'CCA Valuation'!C7 -> 16.950142 | I15: =G15/'CCA Valuation'!C7 -> 19.23395 | J15: ='Master Data (FY26)'!D8/H15 -> 22.657628 | K15: ='Master Data (FY26)'!D8/I15 -> 19.967297
A16: JK Cement | B16: ='Master Data (FY26)'!E4*(1+C8) -> 15368.976 | C16: =B16*(1+D8) -> 17059.563 | D16: =B16*E8 -> 2505.1431 | E16: =C16*F8 -> 2883.0662 | F16: =B16*G8 -> 1014.3524 | G16: =C16*H8 -> 1194.1694 | H16: =F16/'CCA Valuation'!C8 -> 131.27717 | I16: =G16/'CCA Valuation'!C8 -> 154.54903 | J16: ='Master Data (FY26)'!E8/H16 -> 38.318164 | K16: ='Master Data (FY26)'!E8/I16 -> 32.548247
A17: Dalmia Bharat | B17: ='Master Data (FY26)'!F4*(1+C9) -> 16136.36 | C17: =B17*(1+D9) -> 17427.269 | D17: =B17*E9 -> 3065.9084 | E17: =C17*F9 -> 3398.3174 | F17: =B17*G9 -> 1129.5452 | G17: =C17*H9 -> 1272.1906 | H17: =F17/'CCA Valuation'!C9 -> 60.219929 | I17: =G17/'CCA Valuation'!C9 -> 67.824845 | J17: ='Master Data (FY26)'!F8/H17 -> 28.063799 | K17: ='Master Data (FY26)'!F8/I17 -> 24.917123

Sheet Forward & Historical Valuation
A1: Forward & Historical Valuation Cross-Checks
A4: A. Historical implied P/E - current price against FY24-FY26 EPS
A5: Company | B5: FY24 EPS (Rs) | C5: FY25 EPS (Rs) | D5: FY26 EPS (Rs) | E5: Implied P/E on FY24 EPS | F5: Implied P/E on FY25 EPS | G5: Implied P/E on FY26 EPS (=CMP P/E) | H5: 3-Yr Trend Read
A6: UltraTech | B6: =IFERROR('Hist - UltraTech'!B8/'CCA Valuation'!C5,"N/A") -> 238.02243 | C6: =IFERROR('Hist - UltraTech'!C8/'CCA Valuation'!C5,"N/A") -> 205.20217 | D6: =IFERROR('Hist - UltraTech'!D8/'CCA Valuation'!C5,"N/A") -> 277.45973 | E6: =IFERROR('CCA Valuation'!B5/B6,"N/A") -> 45.501175 | F6: =IFERROR('CCA Valuation'!B5/C6,"N/A") -> 52.77868 | G6: =IFERROR('CCA Valuation'!B5/D6,"N/A") -> 39.033772 | H6: =IFERROR(IF(E6>G6,"Multiple compressed as earnings grew","Earnings fell or multiple expanded"),"FY24 not sourced") -> Multiple compressed as earnings grew
A7: Shree Cement | B7: =IFERROR('Hist - Shree'!B8/'CCA Valuation'!C6,"N/A") -> 664.10576 | C7: =IFERROR('Hist - Shree'!C8/'CCA Valuation'!C6,"N/A") -> 311.46587 | D7: =IFERROR('Hist - Shree'!D8/'CCA Valuation'!C6,"N/A") -> 484.64843 | E7: =IFERROR('CCA Valuation'!B6/B7,"N/A") -> 32.990152 | F7: =IFERROR('CCA Valuation'!B6/C7,"N/A") -> 70.341415 | G7: =IFERROR('CCA Valuation'!B6/D7,"N/A") -> 45.205862 | H7: =IFERROR(IF(E7>G7,"Multiple compressed as earnings grew","Earnings fell or multiple expanded"),"FY24 not sourced") -> Earnings fell or multiple expanded
A8: Ambuja | B8: =IFERROR('Hist - Ambuja'!B8/'CCA Valuation'!C7,"N/A") -> 14.002059 | C8: =IFERROR('Hist - Ambuja'!C8/'CCA Valuation'!C7,"N/A") -> 16.861325 | D8: =IFERROR('Hist - Ambuja'!D8/'CCA Valuation'!C7,"N/A") -> 18.527043 | E8: =IFERROR('CCA Valuation'!B7/B8,"N/A") -> 27.428109 | F8: =IFERROR('CCA Valuation'!B7/C8,"N/A") -> 22.776976 | G8: =IFERROR('CCA Valuation'!B7/D8,"N/A") -> 20.729158 | H8: =IFERROR(IF(E8>G8,"Multiple compressed as earnings grew","Earnings fell or multiple expanded"),"FY24 not sourced") -> Multiple compressed as earnings grew
A9: JK Cement | B9: =IFERROR('Hist - JK Cement'!B8/'CCA Valuation'!C8,"N/A") -> 102.34897 | C9: =IFERROR('Hist - JK Cement'!C8/'CCA Valuation'!C8,"N/A") -> 111.44588 | D9: =IFERROR('Hist - JK Cement'!D8/'CCA Valuation'!C8,"N/A") -> 128.44774 | E9: =IFERROR('CCA Valuation'!B8/B9,"N/A") -> 49.148517 | F9: =IFERROR('CCA Valuation'!B8/C9,"N/A") -> 45.136708 | G9: =IFERROR('CCA Valuation'!B8/D9,"N/A") -> 39.16223 | H9: =IFERROR(IF(E9>G9,"Multiple compressed as earnings grew","Earnings fell or multiple expanded"),"FY24 not sourced") -> Multiple compressed as earnings grew
A10: Dalmia Bharat | B10: =IFERROR('Hist - Dalmia'!B8/'CCA Valuation'!C9,"N/A") -> 45.476355 | C10: =IFERROR('Hist - Dalmia'!C8/'CCA Valuation'!C9,"N/A") -> 37.266087 | D10: =IFERROR('Hist - Dalmia'!D8/'CCA Valuation'!C9,"N/A") -> 61.710295 | E10: =IFERROR('CCA Valuation'!B9/B10,"N/A") -> 37.162169 | F10: =IFERROR('CCA Valuation'!B9/C10,"N/A") -> 45.349542 | G10: =IFERROR('CCA Valuation'!B9/D10,"N/A") -> 27.38603 | H10: =IFERROR(IF(E10>G10,"Multiple compressed as earnings grew","Earnings fell or multiple expanded"),"FY24 not sourced") -> Multiple compressed as earnings grew
A14: B. Forward Bear / Base / Bull Valuation - FY28E EPS x convergence-adjusted P/E
A15: Company | B15: FY28E EPS (Rs) | C15: Bear P/E (x) (adjusted -15%) | D15: Base P/E (x) (convergence-adjusted) | E15: Bull P/E (x) (adjusted +15%) | F15: Bear Price (Rs) | G15: Base Price (Rs) | H15: Bull Price (Rs) | I15: Upside/(Downside) to Base vs CMP | J15: Full-convergence price (Rs) | K15: Full-convergence upside
A16: UltraTech | B16: ='FY27-28E Assumptions'!I13 -> 329.76925 | C16: ='Valuation Justification'!N5*0.85 -> 33.178706 | D16: ='Valuation Justification'!N5 -> 39.033772 | E16: ='Valuation Justification'!N5*1.15 -> 44.888838 | F16: =B16*C16 -> 10941.317 | G16: =B16*D16 -> 12872.138 | H16: =B16*E16 -> 14802.958 | I16: =G16/'CCA Valuation'!B5-1 -> 0.1885301 | J16: =B16*'Valuation Justification'!C5 -> 10972.785 | K16: =J16/'CCA Valuation'!B5-1 -> 0.013156137
A17: Shree Cement | B17: ='FY27-28E Assumptions'!I14 -> 561.8824 | C17: ='Valuation Justification'!N6*0.85 -> 33.326699 | D17: ='Valuation Justification'!N6 -> 39.207881 | E17: ='Valuation Justification'!N6*1.15 -> 45.089064 | F17: =B17*C17 -> 18725.686 | G17: =B17*D17 -> 22030.219 | H17: =B17*E17 -> 25334.751 | I17: =G17/'CCA Valuation'!B6-1 -> 0.0055351188 | J17: =B17*'Valuation Justification'!C6 -> 18660.059 | K17: =J17/'CCA Valuation'!B6-1 -> -0.14829058
A18: Ambuja | B18: ='FY27-28E Assumptions'!I15 -> 19.23395 | C18: ='Valuation Justification'!N7*0.85 -> 25.426543 | D18: ='Valuation Justification'!N7 -> 29.91358 | E18: ='Valuation Justification'!N7*1.15 -> 34.400617 | F18: =B18*C18 -> 489.05286 | G18: =B18*D18 -> 575.35631 | H18: =B18*E18 -> 661.65975 | I18: =G18/'CCA Valuation'!B7-1 -> 0.49812865 | J18: =B18*'Valuation Justification'!C7 -> 752.00902 | K18: =J18/'CCA Valuation'!B7-1 -> 0.95810185
A19: JK Cement | B19: ='FY27-28E Assumptions'!I16 -> 154.54903 | C19: ='Valuation Justification'!N8*0.85 -> 32.023026 | D19: ='Valuation Justification'!N8 -> 37.674148 | E19: ='Valuation Justification'!N8*1.15 -> 43.32527 | F19: =B19*C19 -> 4949.1275 | G19: =B19*D19 -> 5822.503 | H19: =B19*E19 -> 6695.8784 | I19: =G19/'CCA Valuation'!B8-1 -> 0.15748623 | J19: =B19*'Valuation Justification'!C8 -> 5132.558 | K19: =J19/'CCA Valuation'!B8-1 -> 0.0203284
A20: Dalmia Bharat | B20: ='FY27-28E Assumptions'!I17 -> 67.824845 | C20: ='Valuation Justification'!N9*0.85 -> 28.255713 | D20: ='Valuation Justification'!N9 -> 33.242016 | E20: ='Valuation Justification'!N9*1.15 -> 38.228318 | F20: =B20*C20 -> 1916.4394 | G20: =B20*D20 -> 2254.6346 | H20: =B20*E20 -> 2592.8298 | I20: =G20/'CCA Valuation'!B9-1 -> 0.3341033 | J20: =B20*'Valuation Justification'!C9 -> 2651.8159 | K20: =J20/'CCA Valuation'!B9-1 -> 0.56912182

Sheet Recommendation Matrix
A1: Recommendation matrix: rule-based rating, short-term and long-term view
A5: Company | B5: Scorecard rank | C5: Forward base upside | D5: CCA upside (convergence-adjusted) | E5: Qualitative score (avg) | F5: Composite risk | G5: Vote: screen | H5: Vote: forward | I5: Vote: CCA | J5: Vote: quality | K5: Vote: risk | L5: Total votes | M5: Rating | N5: FY27E EPS growth | O5: Short-term view (6-12 m) | P5: Planned capacity growth | Q5: Long-term view (3+ yrs)
A6: UltraTech | B6: ='Investment Scorecard'!C15 -> 2 | C6: ='Forward & Historical Valuation'!I16 -> 0.1885301 | D6: ='CCA Valuation'!K5 -> 0 | E6: =AVERAGE('Qualitative Analysis'!B4,'Qualitative Analysis'!C4) -> 4.5 | F6: ='Cost & Risk Assessment'!F15 -> 2.5 | G6: =IF(B6<=#REF!,1,IF(B6>=#REF!,-1,0)) -> #REF! | H6: =IF(C6>=$B$16,1,IF(C6<$B$17,-1,0)) -> 1 | I6: =IF(D6>=$B$18,1,IF(D6<=$B$19,-1,0)) -> 1 | J6: =IF(E6>=$B$20,1,IF(E6<$B$21,-1,0)) -> 1 | K6: =IF(F6<=$B$22,1,IF(F6>=$B$23,-1,0)) -> -1 | L6: =SUM(G6:K6) -> #REF! | M6: =IF(L6>=$B$24,"OVERWEIGHT",IF(L6<=$B$25,"UNDERWEIGHT","HOLD")) -> #REF! | N6: ='FY27-28E Assumptions'!H13/'Forward & Historical Valuation'!D6-1 -> 0.031920927 | O6: =IF(N6>=$B$26,"Positive",IF(N6<0,"Cautious","Neutral")) -> Positive | P6: ='Capacity & Efficiency'!J5 -> 0.1994003 | Q6: =IF(P6>=$B$27,"Positive",IF(P6<$B$14,"Limited","Neutral")) -> Positive
A7: Shree Cement | B7: ='Investment Scorecard'!D15 -> 3 | C7: ='Forward & Historical Valuation'!I17 -> 0.0055351188 | D7: ='CCA Valuation'!K6 -> -0.08926639 | E7: =AVERAGE('Qualitative Analysis'!B5,'Qualitative Analysis'!C5) -> 4 | F7: ='Cost & Risk Assessment'!F16 -> 2.25 | G7: =IF(B7<=#REF!,1,IF(B7>=#REF!,-1,0)) -> #REF! | H7: =IF(C7>=$B$16,1,IF(C7<$B$17,-1,0)) -> 1 | I7: =IF(D7>=$B$18,1,IF(D7<=$B$19,-1,0)) -> -1 | J7: =IF(E7>=$B$20,1,IF(E7<$B$21,-1,0)) -> 1 | K7: =IF(F7<=$B$22,1,IF(F7>=$B$23,-1,0)) -> -1 | L7: =SUM(G7:K7) -> #REF! | M7: =IF(L7>=$B$24,"OVERWEIGHT",IF(L7<=$B$25,"UNDERWEIGHT","HOLD")) -> #REF! | N7: ='FY27-28E Assumptions'!H14/'Forward & Historical Valuation'!D7-1 -> 0.0012661649 | O7: =IF(N7>=$B$26,"Positive",IF(N7<0,"Cautious","Neutral")) -> Positive | P7: ='Capacity & Efficiency'!J6 -> 0.15440115 | Q7: =IF(P7>=$B$27,"Positive",IF(P7<$B$14,"Limited","Neutral")) -> Positive
A8: Ambuja | B8: ='Investment Scorecard'!E15 -> 1 | C8: ='Forward & Historical Valuation'!I18 -> 0.49812865 | D8: ='CCA Valuation'!K7 -> 0.50935071 | E8: =AVERAGE('Qualitative Analysis'!B6,'Qualitative Analysis'!C6) -> 3.5 | F8: ='Cost & Risk Assessment'!F17 -> 2.25 | G8: =IF(B8<=#REF!,1,IF(B8>=#REF!,-1,0)) -> #REF! | H8: =IF(C8>=$B$16,1,IF(C8<$B$17,-1,0)) -> 1 | I8: =IF(D8>=$B$18,1,IF(D8<=$B$19,-1,0)) -> 1 | J8: =IF(E8>=$B$20,1,IF(E8<$B$21,-1,0)) -> 1 | K8: =IF(F8<=$B$22,1,IF(F8>=$B$23,-1,0)) -> -1 | L8: =SUM(G8:K8) -> #REF! | M8: =IF(L8>=$B$24,"OVERWEIGHT",IF(L8<=$B$25,"UNDERWEIGHT","HOLD")) -> #REF! | N8: ='FY27-28E Assumptions'!H15/'Forward & Historical Valuation'!D8-1 -> -0.085113472 | O8: =IF(N8>=$B$26,"Positive",IF(N8<0,"Cautious","Neutral")) -> Cautious | P8: ='Capacity & Efficiency'!J7 -> 0.091743119 | Q8: =IF(P8>=$B$27,"Positive",IF(P8<$B$14,"Limited","Neutral")) -> Positive
